<?xml version="1.0"?>
<robot name="racecar" xmlns:xacro="http://www.ros.org/wiki/xacro">

  <xacro:include filename="$(find f1_robot_model)/urdf/macros.xacro" />
  <xacro:include filename="$(find f1_robot_model)/urdf/imu.xacro"/>
  <xacro:include filename="$(find f1_robot_model)/urdf/auto_inertial.xacro"/>

  <!-- Add chassis and it's inertia link -->

  <link name="base_link" />

  <link name="chassis">
    <visual>
      <xacro:chassis_geometry/>
      <material name="blue" />
    </visual>
    <inertial>
      <xacro:chassis_inertial_params />
    </inertial>
  </link>

  <joint name="base_link_joint" type="fixed">
    <origin xyz="-0.16 0 0" rpy="0 0 0" />
    <parent link="base_link" />
    <child link="chassis" />
  </joint>

  <!-- Robot Footprint -->
  <link name="base_footprint"/>

  <joint name="base_joint" type="fixed">
    <parent link="base_link"/>
    <child link="base_footprint"/>
    <origin xyz="0.0 0.0 -0.05" rpy="0 0 0"/>
  </joint>

  <!-- Add the left rear wheel with its joints and tranmissions -->

  <link name="left_rear_wheel">
    <inertial>
      <xacro:left_wheels_inertial_params />
    </inertial>
    <visual>
      <xacro:left_rear_wheel_geometry />
      <material name="black" />
    </visual>
    <collision>
      <xacro:left_wheels_collision_geometry />
    </collision>
  </link>

  <joint name="left_rear_wheel_joint" type="continuous">
    <origin xyz="0 0.1 0" rpy="1.5708 0 0" />
    <parent link="chassis" />
    <child link="left_rear_wheel" />
    <axis xyz="0 0 -1" />
    <limit effort="10" velocity="100" />
  </joint>

  <xacro:wheel_transmission name="left_rear_wheel" />

  <!-- Add the right rear wheel with its joints and tranmissions -->

  <link name="right_rear_wheel">
    <inertial>
      <xacro:right_wheels_inertial_params />
    </inertial>
    <visual>
      <xacro:right_rear_wheel_geometry />
      <material name="black" />
    </visual>
    <collision>
      <xacro:right_wheels_collision_geometry />
    </collision>
  </link>

  <joint name="right_rear_wheel_joint" type="continuous">
    <origin xyz="0 -0.1 0" rpy="1.5708 0 0" />
    <parent link="chassis" />
    <child link="right_rear_wheel" />
    <axis xyz="0 0 -1" />
    <limit effort="10" velocity="100" />
  </joint>

  <xacro:wheel_transmission name="right_rear_wheel" />

  <!-- Add the left steering hinge with its joints and tranmissions -->

  <link name="left_steering_hinge">
    <inertial>
      <xacro:steering_hinge_inertial_params />
    </inertial>
    <visual>
      <xacro:left_steering_hinge_geometry />
      <material name="grey" />
    </visual>
  </link>

  <joint name="left_steering_hinge_joint" type="revolute">
    <origin xyz="0.325 0.1 0" rpy="0 1.5708 0" />
    <parent link="chassis" />
    <child link="left_steering_hinge" />
    <axis xyz="-1 0 0" />
    <limit lower="-1.0" upper="1.0" effort="10" velocity="100" />
  </joint>

  <xacro:steering_hinge_transmission name="left_steering_hinge" />

  <!-- Add the right steering hinge with its joints and tranmissions -->

  <link name="right_steering_hinge">
    <inertial>
      <xacro:steering_hinge_inertial_params />
    </inertial>
    <visual>
      <xacro:right_steering_hinge_geometry />
      <material name="grey" />
    </visual>
  </link>

  <joint name="right_steering_hinge_joint" type="continuous">
    <origin xyz="0.325 -0.1 0" rpy="0 1.5708 0" />
    <parent link="chassis" />
    <child link="right_steering_hinge" />
    <axis xyz="-1 0 0" />
    <limit lower="-1.0" upper="1.0" effort="10" velocity="100" />
  </joint>

  <xacro:steering_hinge_transmission name="right_steering_hinge" />

  <!-- Add the left front wheel with its joints and tranmissions -->

  <link name="left_front_wheel">
    <inertial>
      <xacro:left_wheels_inertial_params />
    </inertial>
    <visual>
      <xacro:left_front_wheel_geometry />
      <material name="black" />
    </visual>
    <collision>
      <xacro:left_wheels_collision_geometry />
    </collision>
  </link>

  <joint name="left_front_wheel_joint" type="continuous">
    <origin xyz="0 0 0" rpy="1.5708 0 0" />
    <parent link="left_steering_hinge" />
    <child link="left_front_wheel" />
    <axis xyz="0 0 -1" />
    <limit effort="10" velocity="100" />
  </joint>

  <xacro:wheel_transmission name="left_front_wheel" />

  <!-- Add the left front wheel with its joints and tranmissions -->

  <link name="right_front_wheel">
    <inertial>
      <xacro:right_wheels_inertial_params />
    </inertial>
    <visual>
      <xacro:right_front_wheel_geometry />
      <material name="black" />
    </visual>
    <collision>
      <xacro:right_wheels_collision_geometry />
    </collision>
  </link>

  <joint name="right_front_wheel_joint" type="continuous">
    <origin xyz="0 0 0" rpy="1.5708 0 0" />
    <parent link="right_steering_hinge" />
    <child link="right_front_wheel" />
    <axis xyz="0 0 -1" />
    <limit effort="10" velocity="100"/>
  </joint>

  <xacro:wheel_transmission name="right_front_wheel" />

  <!-- Add Hokuyo laser scanner -->

  <link name="laser">
    <inertial>
      <xacro:hokuyo_inertial_params />
    </inertial>
    <collision>
      <origin xyz="0 0 0" rpy="0 0 0"/>
      <geometry>
        <box size="0.1 0.1 0.1"/>
      </geometry>
    </collision>
    <visual>
      <origin xyz="0 0 0" rpy="0 0 0"/>
      <geometry>
        <mesh filename="file://$(find f1_robot_model)/meshes/hokuyo.dae"/>
        <material name="grey" />
      </geometry>
    </visual>
  </link>

  <joint name="hokuyo_joint" type="fixed">
    <origin xyz="0.1 0.0 0.075" rpy="0 0 0"/>
    <parent link="base_link" />
    <child link="laser" />
    <axis xyz="0 0 1" />
  </joint>

  <link name="imu">
    <collision>
      <origin xyz="0 0 0" rpy="0 0 0"/>
      <geometry>
        <box size="0.1 0.1 0.1"/>
      </geometry>
    </collision>
    <visual>
      <origin xyz="0 0 0" rpy="0 0 0"/>
      <geometry>
        <box size="0.01 0.01 0.01"/>
        <material name="blue" />
      </geometry>
    </visual>
  </link>

  <joint name="imu_joint" type="fixed">
    <origin xyz="0.1 0.0 0.025" rpy="0.0 0.0 0.0"/>
    <parent link="base_link"/>
    <child link="imu"/>
    <axis xyz="0.0 0.0 1.0"/>
  </joint>

  <link name="gps">
    <collision>
      <origin xyz="0 0 0" rpy="0 0 0"/>
      <geometry>
        <box size="0.1 0.1 0.1"/>
      </geometry>
    </collision>
    <visual>
      <origin xyz="0 0 0" rpy="0 0 0"/>
      <geometry>
        <box size="0.01 0.01 0.01"/>
        <material name="blue" />
      </geometry>
    </visual>
  </link>

  <joint name="gps_joint" type="fixed">
    <origin xyz="0.1 0.0 0.03" rpy="0.0 0.0 0.0"/>
    <parent link="base_link"/>
    <child link="gps"/>
    <axis xyz="0.0 0.0 1.0"/>
  </joint>

  <!-- Add the remaining xacros -->

  <xacro:include filename="$(find f1_robot_model)/urdf/racecar.gazebo" />
  <xacro:include filename="$(find f1_robot_model)/urdf/materials.xacro" />
  <!--If you want to use Depth camera, Plz Uncomment Code-->
  <!--xacro:include filename="$(find f1_robot_model)/urdf/depth_camera.xacro"/-->

  <!--If you want to use stereo camera with 2-mono camera, Plz Uncomment Codes-->
  <!--xacro:include filename="$(find f1_robot_model)/urdf/left_camera.xacro"/-->
  <!--xacro:include filename="$(find f1_robot_model)/urdf/right_camera.xacro"/-->

  <!--If you want to use 3D LiDAR, Plz Uncomment Code-->
  <!--xacro:include filename="$(find f1_robot_model)/urdf/3dlidar.xacro"/-->

  <!--If you want to use GPS, Plz Uncomment Code-->
  <xacro:include filename="$(find f1_robot_model)/urdf/gps.xacro"/>
</robot>


